Exception in thread DobbyEPLoggerChecker:
Traceback (most recent call last):
  File "/home/dobby/.local/lib/python3.8/site-packages/pymysql/connections.py", line 559, in connect
    sock.connect(self.unix_socket)
FileNotFoundError: [Errno 2] No such file or directory

During handling of the above exception, another exception occurred:

Traceback (most recent call last):
  File "/usr/lib/python3.8/threading.py", line 932, in _bootstrap_inner
    self.run()
  File "/usr/lib/python3.8/threading.py", line 870, in run
    self._target(*self._args, **self._kwargs)
  File "/media/ssd/Dobby/bin2.0/Dobby/dloggingep.py", line 134, in Checker
    db_Connection = self.ddb.Connect(self.Log_db, Create_If_Missing=True)
  File "/media/ssd/Dobby/bin2.0/Dobby/ddb.py", line 31, in Connect
    db = pymysql.connect(
  File "/home/dobby/.local/lib/python3.8/site-packages/pymysql/__init__.py", line 94, in Connect
    return Connection(*args, **kwargs)
  File "/home/dobby/.local/lib/python3.8/site-packages/pymysql/connections.py", line 327, in __init__
    self.connect()
  File "/home/dobby/.local/lib/python3.8/site-packages/pymysql/connections.py", line 619, in connect
    raise exc
pymysql.err.OperationalError: (2003, "Can't connect to MySQL server on 'localhost' ([Errno 2] No such file or directory)")
